<?xml version="1.0" encoding="UTF-8"?>
<testng-results skipped="0" failed="1" total="1" passed="0">
  <reporter-output>
  </reporter-output>
  <suite name="Default suite" duration-ms="54350" started-at="2019-05-02T12:22:21Z" finished-at="2019-05-02T12:23:16Z">
    <groups>
    </groups>
    <test name="Default test" duration-ms="54350" started-at="2019-05-02T12:22:21Z" finished-at="2019-05-02T12:23:16Z">
      <class name="com_SeleniumCodingChallangeSeries2_Test.DepartureRoundTest">
        <test-method status="PASS" signature="Setup()[pri:0, instance:com_SeleniumCodingChallangeSeries2_Test.DepartureRoundTest@7714e963]" name="Setup" is-config="true" duration-ms="12529" started-at="2019-05-02T17:52:21Z" finished-at="2019-05-02T17:52:34Z">
          <reporter-output>
          </reporter-output>
        </test-method> <!-- Setup -->
        <test-method status="FAIL" signature="NumberOfDepartureFlights()[pri:0, instance:com_SeleniumCodingChallangeSeries2_Test.DepartureRoundTest@7714e963]" name="NumberOfDepartureFlights" duration-ms="40904" started-at="2019-05-02T17:52:34Z" finished-at="2019-05-02T17:53:15Z">
          <exception class="java.lang.AssertionError">
            <message>
              <![CDATA[expected [true] but found [false]]]>
            </message>
            <full-stacktrace>
              <![CDATA[java.lang.AssertionError: expected [true] but found [false]
	at org.testng.Assert.fail(Assert.java:94)
	at org.testng.Assert.failNotEquals(Assert.java:513)
	at org.testng.Assert.assertTrue(Assert.java:42)
	at org.testng.Assert.assertTrue(Assert.java:52)
	at com_SeleniumCodingChallangeSeries2_Test.DepartureRoundTest.NumberOfDepartureFlights(DepartureRoundTest.java:58)
	at sun.reflect.NativeMethodAccessorImpl.invoke0(Native Method)
	at sun.reflect.NativeMethodAccessorImpl.invoke(NativeMethodAccessorImpl.java:62)
	at sun.reflect.DelegatingMethodAccessorImpl.invoke(DelegatingMethodAccessorImpl.java:43)
	at java.lang.reflect.Method.invoke(Method.java:498)
	at org.testng.internal.MethodInvocationHelper.invokeMethod(MethodInvocationHelper.java:86)
	at org.testng.internal.Invoker.invokeMethod(Invoker.java:645)
	at org.testng.internal.Invoker.invokeTestMethod(Invoker.java:822)
	at org.testng.internal.Invoker.invokeTestMethods(Invoker.java:1130)
	at org.testng.internal.TestMethodWorker.invokeTestMethods(TestMethodWorker.java:129)
	at org.testng.internal.TestMethodWorker.run(TestMethodWorker.java:112)
	at org.testng.TestRunner.privateRun(TestRunner.java:782)
	at org.testng.TestRunner.run(TestRunner.java:632)
	at org.testng.SuiteRunner.runTest(SuiteRunner.java:366)
	at org.testng.SuiteRunner.runSequentially(SuiteRunner.java:361)
	at org.testng.SuiteRunner.privateRun(SuiteRunner.java:319)
	at org.testng.SuiteRunner.run(SuiteRunner.java:268)
	at org.testng.SuiteRunnerWorker.runSuite(SuiteRunnerWorker.java:52)
	at org.testng.SuiteRunnerWorker.run(SuiteRunnerWorker.java:86)
	at org.testng.TestNG.runSuitesSequentially(TestNG.java:1244)
	at org.testng.TestNG.runSuitesLocally(TestNG.java:1169)
	at org.testng.TestNG.run(TestNG.java:1064)
	at org.testng.remote.RemoteTestNG.run(RemoteTestNG.java:113)
	at org.testng.remote.RemoteTestNG.initAndRun(RemoteTestNG.java:206)
	at org.testng.remote.RemoteTestNG.main(RemoteTestNG.java:177)
]]>
            </full-stacktrace>
          </exception> <!-- java.lang.AssertionError -->
          <reporter-output>
          </reporter-output>
        </test-method> <!-- NumberOfDepartureFlights -->
        <test-method status="PASS" signature="TearDown()[pri:0, instance:com_SeleniumCodingChallangeSeries2_Test.DepartureRoundTest@7714e963]" name="TearDown" is-config="true" duration-ms="890" started-at="2019-05-02T17:53:15Z" finished-at="2019-05-02T17:53:16Z">
          <reporter-output>
          </reporter-output>
        </test-method> <!-- TearDown -->
      </class> <!-- com_SeleniumCodingChallangeSeries2_Test.DepartureRoundTest -->
    </test> <!-- Default test -->
  </suite> <!-- Default suite -->
</testng-results>
